<?xml version='1.0' encoding='utf-8'?>
<robot name="swingboy">
  <link name="left_knee_wheel_link">
    <inertial>
      <origin xyz="0.10188940 0.00541451 -0.14304925" rpy="0 0 0" />
      <mass value="0.765" />
      <inertia ixx="0.00399113509" iyy="0.00596078671" izz="0.00215670103" ixy="2.04041233e-05" iyz="-2.67962665e-05" ixz="0.00261767321" />
    </inertial>
    <visual>
      <origin xyz="0.092067 0.120369 -0.199206" rpy="0 0 0" />
      <geometry>
        <mesh filename="meshes/left_knee_wheel_link.stl" scale="0.001 0.001 0.001" />
      </geometry>
    </visual>
    <collision>
      <origin xyz="0.092067 0.120369 -0.199206" rpy="0 0 0" />
      <geometry>
        <mesh filename="meshes/left_knee_wheel_link.stl" scale="0.001 0.001 0.001" />
      </geometry>
    </collision>
  </link>
  <link name="base_link">
    <inertial>
      <origin xyz="0.01619223 -0.00590077 0.03338208" rpy="0 0 0" />
      <mass value="1.837" />
      <inertia ixx="0.00538627411" iyy="0.0100421857" izz="0.00930933319" ixy="-1.68124636e-05" iyz="-2.24216996e-06" ixz="-0.00215963550" />
    </inertial>
    <visual>
      <origin xyz="0 0 0" rpy="0 0 0" />
      <geometry>
        <mesh filename="meshes/base_link.stl" scale="0.001 0.001 0.001" />
      </geometry>
    </visual>
    <collision>
      <origin xyz="0 0 0" rpy="0 0 0" />
      <geometry>
        <mesh filename="meshes/base_link.stl" scale="0.001 0.001 0.001" />
      </geometry>
    </collision>
  </link>
  <link name="left_hip_knee_link">
    <inertial>
      <origin xyz="-0.02277463 -0.03418610 0.10739150" rpy="0 0 0" />
      <mass value="1.293" />
      <inertia ixx="0.0144272682" iyy="0.0150014080" izz="0.00144285072" ixy="1.13209663e-05" iyz="-1.70128250e-05" ixz="0.00289102751" />
    </inertial>
    <visual>
      <origin xyz="0.046391 0.120369 0.016" rpy="0 0 0" />
      <geometry>
        <mesh filename="meshes/left_hip_knee_link.stl" scale="0.001 0.001 0.001" />
      </geometry>
    </visual>
    <collision>
      <origin xyz="0.046391 0.120369 0.016" rpy="0 0 0" />
      <geometry>
        <mesh filename="meshes/left_hip_knee_link.stl" scale="0.001 0.001 0.001" />
      </geometry>
    </collision>
  </link>
  <link name="left_wheel">
    <inertial>
      <origin xyz="-1.61359426e-07 -0.00316087763 -9.15398555e-07" rpy="0 0 0" />
      <mass value="0.233" />
      <inertia ixx="0.000304882351" iyy="0.000581979599" izz="0.000305007970" ixy="-1.83366311e-10" iyz="-1.44718863e-10" ixz="-5.19940117e-08" />
    </inertial>
    <visual>
      <origin xyz="-0.047147 0.142869 -0.003709" rpy="0 0 0" />
      <geometry>
        <mesh filename="meshes/left_wheel.stl" scale="0.001 0.001 0.001" />
      </geometry>
    </visual>
    <collision>
      <origin xyz="-0.047147 0.142869 -0.003709" rpy="0 0 0" />
      <geometry>
        <mesh filename="meshes/left_wheel.stl" scale="0.001 0.001 0.001" />
      </geometry>
    </collision>
  </link>
  <link name="right_hip_knee_link">
    <inertial>
      <origin xyz="-0.02272135 0.03434838 0.10691437" rpy="0 0 0" />
      <mass value="1.293" />
      <inertia ixx="0.0144777946" iyy="0.0150598797" izz="0.00144426730" ixy="-9.30836692e-06" iyz="1.09849902e-05" ixz="0.00290762418" />
    </inertial>
    <visual>
      <origin xyz="0.046391 -0.110369 0.016" rpy="0 0 0" />
      <geometry>
        <mesh filename="meshes/right_hip_knee_link.stl" scale="0.001 0.001 0.001" />
      </geometry>
    </visual>
    <collision>
      <origin xyz="0.046391 -0.110369 0.016" rpy="0 0 0" />
      <geometry>
        <mesh filename="meshes/right_hip_knee_link.stl" scale="0.001 0.001 0.001" />
      </geometry>
    </collision>
  </link>
  <link name="right_knee_wheel_link">
    <inertial>
      <origin xyz="0.10266849 -0.00539423 -0.14402274" rpy="0 0 0" />
      <mass value="0.765" />
      <inertia ixx="0.00388606061" iyy="0.00582047846" izz="0.00212276094" ixy="-1.87402153e-05" iyz="2.64224649e-05" ixz="0.00255420843" />
    </inertial>
    <visual>
      <origin xyz="0.092132 -0.110369 -0.199192" rpy="0 0 0" />
      <geometry>
        <mesh filename="meshes/right_knee_wheel_link.stl" scale="0.001 0.001 0.001" />
      </geometry>
    </visual>
    <collision>
      <origin xyz="0.092132 -0.110369 -0.199192" rpy="0 0 0" />
      <geometry>
        <mesh filename="meshes/right_knee_wheel_link.stl" scale="0.001 0.001 0.001" />
      </geometry>
    </collision>
  </link>
  <link name="right_wheel">
    <inertial>
      <origin xyz="-6.79156997e-08 0.00316097940 -7.39187110e-07" rpy="0 0 0" />
      <mass value="0.233" />
      <inertia ixx="0.000304906894" iyy="0.000581979596" izz="0.000304983433" ixy="1.69998270e-10" iyz="1.59049762e-10" ixz="-1.08810117e-07" />
    </inertial>
    <visual>
      <origin xyz="-0.047141 -0.132869 -0.003737" rpy="0 0 0" />
      <geometry>
        <mesh filename="meshes/right_wheel.stl" scale="0.001 0.001 0.001" />
      </geometry>
    </visual>
    <collision>
      <origin xyz="-0.047141 -0.132869 -0.003737" rpy="0 0 0" />
      <geometry>
        <mesh filename="meshes/right_wheel.stl" scale="0.001 0.001 0.001" />
      </geometry>
    </collision>
  </link>
  <joint name="left_hip" type="revolute">
    <origin xyz="-0.046391 -0.120369 -0.016" rpy="0 0 0" />
    <parent link="base_link" />
    <child link="left_hip_knee_link" />
    <axis xyz="0 1 0" />
    <limit lower="0.0" upper="2.2689280276" effort="30.5" velocity="15.49" />
    <dynamics damping="0.08" friction="0.0" />
  </joint>
  <joint name="right_hip" type="revolute">
    <origin xyz="-0.046391 0.110369 -0.016" rpy="0 0 0" />
    <parent link="base_link" />
    <child link="right_hip_knee_link" />
    <axis xyz="0 1 0" />
    <limit lower="0.0" upper="2.2689280276" effort="30.5" velocity="15.49" />
    <dynamics damping="0.08" friction="0.0" />
  </joint>
  <joint name="right_knee" type="revolute">
    <origin xyz="-0.045741 0 0.215192" rpy="0 0 0" />
    <parent link="right_hip_knee_link" />
    <child link="right_knee_wheel_link" />
    <axis xyz="0 -1 0" />
    <limit lower="0.0872664626" upper="5.0614548308" effort="30.5" velocity="15.49" />
    <dynamics damping="0.08" friction="0.0" />
  </joint>
  <joint name="right_wheel" type="continuous">
    <origin xyz="0.139273 0.0225 -0.195455" rpy="0 0 0" />
    <parent link="right_knee_wheel_link" />
    <child link="right_wheel" />
    <axis xyz="0 1 0" />
    <limit effort="19.94" velocity="24.18" />
    <dynamics damping="0.02" friction="0.0" />
  </joint>
  <joint name="left_knee" type="revolute">
    <origin xyz="-0.045676 0 0.215206" rpy="0 0 0" />
    <parent link="left_hip_knee_link" />
    <child link="left_knee_wheel_link" />
    <axis xyz="0 -1 0" />
    <limit lower="0.0872664626" upper="5.0614548308" effort="30.5" velocity="15.49" />
    <dynamics damping="0.08" friction="0.0" />
  </joint>
  <joint name="left_wheel" type="continuous">
    <origin xyz="0.139214 -0.0225 -0.195497" rpy="0 0 0" />
    <parent link="left_knee_wheel_link" />
    <child link="left_wheel" />
    <axis xyz="0 -1 0" />
    <limit effort="19.94" velocity="24.18" />
    <dynamics damping="0.02" friction="0.0" />
  </joint>
</robot>
